2025-05-03 02:48:08,296 - CRITICAL - 程序异常终止: Elasticsearch.__init__() got an unexpected keyword argument 'timeout'
Traceback (most recent call last):
  File "/home/petto/news_search/index/es_indexer.py", line 134, in <module>
    es = Elasticsearch(
TypeError: Elasticsearch.__init__() got an unexpected keyword argument 'timeout'
2025-05-03 02:51:30,796 - INFO - HEAD http://localhost:9200/ [status:N/A duration:0.092s]
2025-05-03 02:51:30,796 - WARNING - Node <Urllib3HttpNode(http://localhost:9200)> has failed for 1 times in a row, putting on 1 second timeout
2025-05-03 02:51:30,796 - WARNING - Retrying request after failure (attempt 0 of 3)
Traceback (most recent call last):
  File "/home/petto/news_search/venv/lib/python3.10/site-packages/urllib3/connectionpool.py", line 787, in urlopen
    response = self._make_request(
  File "/home/petto/news_search/venv/lib/python3.10/site-packages/urllib3/connectionpool.py", line 534, in _make_request
    response = conn.getresponse()
  File "/home/petto/news_search/venv/lib/python3.10/site-packages/urllib3/connection.py", line 516, in getresponse
    httplib_response = super().getresponse()
  File "/usr/lib/python3.10/http/client.py", line 1375, in getresponse
    response.begin()
  File "/usr/lib/python3.10/http/client.py", line 318, in begin
    version, status, reason = self._read_status()
  File "/usr/lib/python3.10/http/client.py", line 287, in _read_status
    raise RemoteDisconnected("Remote end closed connection without"
http.client.RemoteDisconnected: Remote end closed connection without response

During handling of the above exception, another exception occurred:

Traceback (most recent call last):
  File "/home/petto/news_search/venv/lib/python3.10/site-packages/elastic_transport/_node/_http_urllib3.py", line 167, in perform_request
    response = self.pool.urlopen(
  File "/home/petto/news_search/venv/lib/python3.10/site-packages/urllib3/connectionpool.py", line 841, in urlopen
    retries = retries.increment(
  File "/home/petto/news_search/venv/lib/python3.10/site-packages/urllib3/util/retry.py", line 449, in increment
    raise reraise(type(error), error, _stacktrace)
  File "/home/petto/news_search/venv/lib/python3.10/site-packages/urllib3/util/util.py", line 38, in reraise
    raise value.with_traceback(tb)
  File "/home/petto/news_search/venv/lib/python3.10/site-packages/urllib3/connectionpool.py", line 787, in urlopen
    response = self._make_request(
  File "/home/petto/news_search/venv/lib/python3.10/site-packages/urllib3/connectionpool.py", line 534, in _make_request
    response = conn.getresponse()
  File "/home/petto/news_search/venv/lib/python3.10/site-packages/urllib3/connection.py", line 516, in getresponse
    httplib_response = super().getresponse()
  File "/usr/lib/python3.10/http/client.py", line 1375, in getresponse
    response.begin()
  File "/usr/lib/python3.10/http/client.py", line 318, in begin
    version, status, reason = self._read_status()
  File "/usr/lib/python3.10/http/client.py", line 287, in _read_status
    raise RemoteDisconnected("Remote end closed connection without"
urllib3.exceptions.ProtocolError: ('Connection aborted.', RemoteDisconnected('Remote end closed connection without response'))

The above exception was the direct cause of the following exception:

Traceback (most recent call last):
  File "/home/petto/news_search/venv/lib/python3.10/site-packages/elastic_transport/_transport.py", line 342, in perform_request
    resp = node.perform_request(
  File "/home/petto/news_search/venv/lib/python3.10/site-packages/elastic_transport/_node/_http_urllib3.py", line 202, in perform_request
    raise err from e
elastic_transport.ConnectionError: Connection error caused by: ProtocolError(('Connection aborted.', RemoteDisconnected('Remote end closed connection without response')))
2025-05-03 02:51:30,801 - INFO - HEAD http://localhost:9200/ [status:N/A duration:0.003s]
2025-05-03 02:51:30,801 - WARNING - Node <Urllib3HttpNode(http://localhost:9200)> has failed for 2 times in a row, putting on 2 second timeout
2025-05-03 02:51:30,801 - WARNING - Retrying request after failure (attempt 1 of 3)
Traceback (most recent call last):
  File "/home/petto/news_search/venv/lib/python3.10/site-packages/urllib3/connectionpool.py", line 787, in urlopen
    response = self._make_request(
  File "/home/petto/news_search/venv/lib/python3.10/site-packages/urllib3/connectionpool.py", line 534, in _make_request
    response = conn.getresponse()
  File "/home/petto/news_search/venv/lib/python3.10/site-packages/urllib3/connection.py", line 516, in getresponse
    httplib_response = super().getresponse()
  File "/usr/lib/python3.10/http/client.py", line 1375, in getresponse
    response.begin()
  File "/usr/lib/python3.10/http/client.py", line 318, in begin
    version, status, reason = self._read_status()
  File "/usr/lib/python3.10/http/client.py", line 287, in _read_status
    raise RemoteDisconnected("Remote end closed connection without"
http.client.RemoteDisconnected: Remote end closed connection without response

During handling of the above exception, another exception occurred:

Traceback (most recent call last):
  File "/home/petto/news_search/venv/lib/python3.10/site-packages/elastic_transport/_node/_http_urllib3.py", line 167, in perform_request
    response = self.pool.urlopen(
  File "/home/petto/news_search/venv/lib/python3.10/site-packages/urllib3/connectionpool.py", line 841, in urlopen
    retries = retries.increment(
  File "/home/petto/news_search/venv/lib/python3.10/site-packages/urllib3/util/retry.py", line 449, in increment
    raise reraise(type(error), error, _stacktrace)
  File "/home/petto/news_search/venv/lib/python3.10/site-packages/urllib3/util/util.py", line 38, in reraise
    raise value.with_traceback(tb)
  File "/home/petto/news_search/venv/lib/python3.10/site-packages/urllib3/connectionpool.py", line 787, in urlopen
    response = self._make_request(
  File "/home/petto/news_search/venv/lib/python3.10/site-packages/urllib3/connectionpool.py", line 534, in _make_request
    response = conn.getresponse()
  File "/home/petto/news_search/venv/lib/python3.10/site-packages/urllib3/connection.py", line 516, in getresponse
    httplib_response = super().getresponse()
  File "/usr/lib/python3.10/http/client.py", line 1375, in getresponse
    response.begin()
  File "/usr/lib/python3.10/http/client.py", line 318, in begin
    version, status, reason = self._read_status()
  File "/usr/lib/python3.10/http/client.py", line 287, in _read_status
    raise RemoteDisconnected("Remote end closed connection without"
urllib3.exceptions.ProtocolError: ('Connection aborted.', RemoteDisconnected('Remote end closed connection without response'))

The above exception was the direct cause of the following exception:

Traceback (most recent call last):
  File "/home/petto/news_search/venv/lib/python3.10/site-packages/elastic_transport/_transport.py", line 342, in perform_request
    resp = node.perform_request(
  File "/home/petto/news_search/venv/lib/python3.10/site-packages/elastic_transport/_node/_http_urllib3.py", line 202, in perform_request
    raise err from e
elastic_transport.ConnectionError: Connection error caused by: ProtocolError(('Connection aborted.', RemoteDisconnected('Remote end closed connection without response')))
2025-05-03 02:51:30,805 - INFO - HEAD http://localhost:9200/ [status:N/A duration:0.003s]
2025-05-03 02:51:30,805 - WARNING - Node <Urllib3HttpNode(http://localhost:9200)> has failed for 3 times in a row, putting on 4 second timeout
2025-05-03 02:51:30,805 - WARNING - Retrying request after failure (attempt 2 of 3)
Traceback (most recent call last):
  File "/home/petto/news_search/venv/lib/python3.10/site-packages/urllib3/connectionpool.py", line 787, in urlopen
    response = self._make_request(
  File "/home/petto/news_search/venv/lib/python3.10/site-packages/urllib3/connectionpool.py", line 534, in _make_request
    response = conn.getresponse()
  File "/home/petto/news_search/venv/lib/python3.10/site-packages/urllib3/connection.py", line 516, in getresponse
    httplib_response = super().getresponse()
  File "/usr/lib/python3.10/http/client.py", line 1375, in getresponse
    response.begin()
  File "/usr/lib/python3.10/http/client.py", line 318, in begin
    version, status, reason = self._read_status()
  File "/usr/lib/python3.10/http/client.py", line 287, in _read_status
    raise RemoteDisconnected("Remote end closed connection without"
http.client.RemoteDisconnected: Remote end closed connection without response

During handling of the above exception, another exception occurred:

Traceback (most recent call last):
  File "/home/petto/news_search/venv/lib/python3.10/site-packages/elastic_transport/_node/_http_urllib3.py", line 167, in perform_request
    response = self.pool.urlopen(
  File "/home/petto/news_search/venv/lib/python3.10/site-packages/urllib3/connectionpool.py", line 841, in urlopen
    retries = retries.increment(
  File "/home/petto/news_search/venv/lib/python3.10/site-packages/urllib3/util/retry.py", line 449, in increment
    raise reraise(type(error), error, _stacktrace)
  File "/home/petto/news_search/venv/lib/python3.10/site-packages/urllib3/util/util.py", line 38, in reraise
    raise value.with_traceback(tb)
  File "/home/petto/news_search/venv/lib/python3.10/site-packages/urllib3/connectionpool.py", line 787, in urlopen
    response = self._make_request(
  File "/home/petto/news_search/venv/lib/python3.10/site-packages/urllib3/connectionpool.py", line 534, in _make_request
    response = conn.getresponse()
  File "/home/petto/news_search/venv/lib/python3.10/site-packages/urllib3/connection.py", line 516, in getresponse
    httplib_response = super().getresponse()
  File "/usr/lib/python3.10/http/client.py", line 1375, in getresponse
    response.begin()
  File "/usr/lib/python3.10/http/client.py", line 318, in begin
    version, status, reason = self._read_status()
  File "/usr/lib/python3.10/http/client.py", line 287, in _read_status
    raise RemoteDisconnected("Remote end closed connection without"
urllib3.exceptions.ProtocolError: ('Connection aborted.', RemoteDisconnected('Remote end closed connection without response'))

The above exception was the direct cause of the following exception:

Traceback (most recent call last):
  File "/home/petto/news_search/venv/lib/python3.10/site-packages/elastic_transport/_transport.py", line 342, in perform_request
    resp = node.perform_request(
  File "/home/petto/news_search/venv/lib/python3.10/site-packages/elastic_transport/_node/_http_urllib3.py", line 202, in perform_request
    raise err from e
elastic_transport.ConnectionError: Connection error caused by: ProtocolError(('Connection aborted.', RemoteDisconnected('Remote end closed connection without response')))
2025-05-03 02:51:30,808 - INFO - HEAD http://localhost:9200/ [status:N/A duration:0.003s]
2025-05-03 02:51:30,808 - WARNING - Node <Urllib3HttpNode(http://localhost:9200)> has failed for 4 times in a row, putting on 8 second timeout
2025-05-03 02:51:30,808 - CRITICAL - 程序异常终止: 无法连接到 Elasticsearch
Traceback (most recent call last):
  File "/home/petto/news_search/index/es_indexer.py", line 140, in <module>
    raise ConnectionError("无法连接到 Elasticsearch")
ConnectionError: 无法连接到 Elasticsearch
2025-05-03 02:52:50,061 - INFO - HEAD http://localhost:9200/ [status:N/A duration:0.003s]
2025-05-03 02:52:50,061 - WARNING - Node <Urllib3HttpNode(http://localhost:9200)> has failed for 1 times in a row, putting on 1 second timeout
2025-05-03 02:52:50,061 - WARNING - Retrying request after failure (attempt 0 of 3)
Traceback (most recent call last):
  File "/home/petto/news_search/venv/lib/python3.10/site-packages/urllib3/connectionpool.py", line 787, in urlopen
    response = self._make_request(
  File "/home/petto/news_search/venv/lib/python3.10/site-packages/urllib3/connectionpool.py", line 534, in _make_request
    response = conn.getresponse()
  File "/home/petto/news_search/venv/lib/python3.10/site-packages/urllib3/connection.py", line 516, in getresponse
    httplib_response = super().getresponse()
  File "/usr/lib/python3.10/http/client.py", line 1375, in getresponse
    response.begin()
  File "/usr/lib/python3.10/http/client.py", line 318, in begin
    version, status, reason = self._read_status()
  File "/usr/lib/python3.10/http/client.py", line 287, in _read_status
    raise RemoteDisconnected("Remote end closed connection without"
http.client.RemoteDisconnected: Remote end closed connection without response

During handling of the above exception, another exception occurred:

Traceback (most recent call last):
  File "/home/petto/news_search/venv/lib/python3.10/site-packages/elastic_transport/_node/_http_urllib3.py", line 167, in perform_request
    response = self.pool.urlopen(
  File "/home/petto/news_search/venv/lib/python3.10/site-packages/urllib3/connectionpool.py", line 841, in urlopen
    retries = retries.increment(
  File "/home/petto/news_search/venv/lib/python3.10/site-packages/urllib3/util/retry.py", line 449, in increment
    raise reraise(type(error), error, _stacktrace)
  File "/home/petto/news_search/venv/lib/python3.10/site-packages/urllib3/util/util.py", line 38, in reraise
    raise value.with_traceback(tb)
  File "/home/petto/news_search/venv/lib/python3.10/site-packages/urllib3/connectionpool.py", line 787, in urlopen
    response = self._make_request(
  File "/home/petto/news_search/venv/lib/python3.10/site-packages/urllib3/connectionpool.py", line 534, in _make_request
    response = conn.getresponse()
  File "/home/petto/news_search/venv/lib/python3.10/site-packages/urllib3/connection.py", line 516, in getresponse
    httplib_response = super().getresponse()
  File "/usr/lib/python3.10/http/client.py", line 1375, in getresponse
    response.begin()
  File "/usr/lib/python3.10/http/client.py", line 318, in begin
    version, status, reason = self._read_status()
  File "/usr/lib/python3.10/http/client.py", line 287, in _read_status
    raise RemoteDisconnected("Remote end closed connection without"
urllib3.exceptions.ProtocolError: ('Connection aborted.', RemoteDisconnected('Remote end closed connection without response'))

The above exception was the direct cause of the following exception:

Traceback (most recent call last):
  File "/home/petto/news_search/venv/lib/python3.10/site-packages/elastic_transport/_transport.py", line 342, in perform_request
    resp = node.perform_request(
  File "/home/petto/news_search/venv/lib/python3.10/site-packages/elastic_transport/_node/_http_urllib3.py", line 202, in perform_request
    raise err from e
elastic_transport.ConnectionError: Connection error caused by: ProtocolError(('Connection aborted.', RemoteDisconnected('Remote end closed connection without response')))
2025-05-03 02:52:50,064 - INFO - HEAD http://localhost:9200/ [status:N/A duration:0.002s]
2025-05-03 02:52:50,064 - WARNING - Node <Urllib3HttpNode(http://localhost:9200)> has failed for 2 times in a row, putting on 2 second timeout
2025-05-03 02:52:50,064 - WARNING - Retrying request after failure (attempt 1 of 3)
Traceback (most recent call last):
  File "/home/petto/news_search/venv/lib/python3.10/site-packages/urllib3/connectionpool.py", line 787, in urlopen
    response = self._make_request(
  File "/home/petto/news_search/venv/lib/python3.10/site-packages/urllib3/connectionpool.py", line 534, in _make_request
    response = conn.getresponse()
  File "/home/petto/news_search/venv/lib/python3.10/site-packages/urllib3/connection.py", line 516, in getresponse
    httplib_response = super().getresponse()
  File "/usr/lib/python3.10/http/client.py", line 1375, in getresponse
    response.begin()
  File "/usr/lib/python3.10/http/client.py", line 318, in begin
    version, status, reason = self._read_status()
  File "/usr/lib/python3.10/http/client.py", line 287, in _read_status
    raise RemoteDisconnected("Remote end closed connection without"
http.client.RemoteDisconnected: Remote end closed connection without response

During handling of the above exception, another exception occurred:

Traceback (most recent call last):
  File "/home/petto/news_search/venv/lib/python3.10/site-packages/elastic_transport/_node/_http_urllib3.py", line 167, in perform_request
    response = self.pool.urlopen(
  File "/home/petto/news_search/venv/lib/python3.10/site-packages/urllib3/connectionpool.py", line 841, in urlopen
    retries = retries.increment(
  File "/home/petto/news_search/venv/lib/python3.10/site-packages/urllib3/util/retry.py", line 449, in increment
    raise reraise(type(error), error, _stacktrace)
  File "/home/petto/news_search/venv/lib/python3.10/site-packages/urllib3/util/util.py", line 38, in reraise
    raise value.with_traceback(tb)
  File "/home/petto/news_search/venv/lib/python3.10/site-packages/urllib3/connectionpool.py", line 787, in urlopen
    response = self._make_request(
  File "/home/petto/news_search/venv/lib/python3.10/site-packages/urllib3/connectionpool.py", line 534, in _make_request
    response = conn.getresponse()
  File "/home/petto/news_search/venv/lib/python3.10/site-packages/urllib3/connection.py", line 516, in getresponse
    httplib_response = super().getresponse()
  File "/usr/lib/python3.10/http/client.py", line 1375, in getresponse
    response.begin()
  File "/usr/lib/python3.10/http/client.py", line 318, in begin
    version, status, reason = self._read_status()
  File "/usr/lib/python3.10/http/client.py", line 287, in _read_status
    raise RemoteDisconnected("Remote end closed connection without"
urllib3.exceptions.ProtocolError: ('Connection aborted.', RemoteDisconnected('Remote end closed connection without response'))

The above exception was the direct cause of the following exception:

Traceback (most recent call last):
  File "/home/petto/news_search/venv/lib/python3.10/site-packages/elastic_transport/_transport.py", line 342, in perform_request
    resp = node.perform_request(
  File "/home/petto/news_search/venv/lib/python3.10/site-packages/elastic_transport/_node/_http_urllib3.py", line 202, in perform_request
    raise err from e
elastic_transport.ConnectionError: Connection error caused by: ProtocolError(('Connection aborted.', RemoteDisconnected('Remote end closed connection without response')))
2025-05-03 02:52:50,066 - INFO - HEAD http://localhost:9200/ [status:N/A duration:0.002s]
2025-05-03 02:52:50,066 - WARNING - Node <Urllib3HttpNode(http://localhost:9200)> has failed for 3 times in a row, putting on 4 second timeout
2025-05-03 02:52:50,066 - WARNING - Retrying request after failure (attempt 2 of 3)
Traceback (most recent call last):
  File "/home/petto/news_search/venv/lib/python3.10/site-packages/urllib3/connectionpool.py", line 787, in urlopen
    response = self._make_request(
  File "/home/petto/news_search/venv/lib/python3.10/site-packages/urllib3/connectionpool.py", line 534, in _make_request
    response = conn.getresponse()
  File "/home/petto/news_search/venv/lib/python3.10/site-packages/urllib3/connection.py", line 516, in getresponse
    httplib_response = super().getresponse()
  File "/usr/lib/python3.10/http/client.py", line 1375, in getresponse
    response.begin()
  File "/usr/lib/python3.10/http/client.py", line 318, in begin
    version, status, reason = self._read_status()
  File "/usr/lib/python3.10/http/client.py", line 287, in _read_status
    raise RemoteDisconnected("Remote end closed connection without"
http.client.RemoteDisconnected: Remote end closed connection without response

During handling of the above exception, another exception occurred:

Traceback (most recent call last):
  File "/home/petto/news_search/venv/lib/python3.10/site-packages/elastic_transport/_node/_http_urllib3.py", line 167, in perform_request
    response = self.pool.urlopen(
  File "/home/petto/news_search/venv/lib/python3.10/site-packages/urllib3/connectionpool.py", line 841, in urlopen
    retries = retries.increment(
  File "/home/petto/news_search/venv/lib/python3.10/site-packages/urllib3/util/retry.py", line 449, in increment
    raise reraise(type(error), error, _stacktrace)
  File "/home/petto/news_search/venv/lib/python3.10/site-packages/urllib3/util/util.py", line 38, in reraise
    raise value.with_traceback(tb)
  File "/home/petto/news_search/venv/lib/python3.10/site-packages/urllib3/connectionpool.py", line 787, in urlopen
    response = self._make_request(
  File "/home/petto/news_search/venv/lib/python3.10/site-packages/urllib3/connectionpool.py", line 534, in _make_request
    response = conn.getresponse()
  File "/home/petto/news_search/venv/lib/python3.10/site-packages/urllib3/connection.py", line 516, in getresponse
    httplib_response = super().getresponse()
  File "/usr/lib/python3.10/http/client.py", line 1375, in getresponse
    response.begin()
  File "/usr/lib/python3.10/http/client.py", line 318, in begin
    version, status, reason = self._read_status()
  File "/usr/lib/python3.10/http/client.py", line 287, in _read_status
    raise RemoteDisconnected("Remote end closed connection without"
urllib3.exceptions.ProtocolError: ('Connection aborted.', RemoteDisconnected('Remote end closed connection without response'))

The above exception was the direct cause of the following exception:

Traceback (most recent call last):
  File "/home/petto/news_search/venv/lib/python3.10/site-packages/elastic_transport/_transport.py", line 342, in perform_request
    resp = node.perform_request(
  File "/home/petto/news_search/venv/lib/python3.10/site-packages/elastic_transport/_node/_http_urllib3.py", line 202, in perform_request
    raise err from e
elastic_transport.ConnectionError: Connection error caused by: ProtocolError(('Connection aborted.', RemoteDisconnected('Remote end closed connection without response')))
2025-05-03 02:52:50,069 - INFO - HEAD http://localhost:9200/ [status:N/A duration:0.002s]
2025-05-03 02:52:50,069 - WARNING - Node <Urllib3HttpNode(http://localhost:9200)> has failed for 4 times in a row, putting on 8 second timeout
2025-05-03 02:52:50,069 - CRITICAL - 程序异常终止: 无法连接到 Elasticsearch
Traceback (most recent call last):
  File "/home/petto/news_search/index/es_indexer.py", line 140, in <module>
    raise ConnectionError("无法连接到 Elasticsearch")
ConnectionError: 无法连接到 Elasticsearch
2025-05-03 02:53:17,519 - CRITICAL - 程序异常终止: Elasticsearch.__init__() got an unexpected keyword argument 'timeout'
Traceback (most recent call last):
  File "/home/petto/news_search/index/es_indexer.py", line 134, in <module>
    es = Elasticsearch(
TypeError: Elasticsearch.__init__() got an unexpected keyword argument 'timeout'
2025-05-03 03:12:03,477 - CRITICAL - 程序异常终止: Elasticsearch.__init__() got an unexpected keyword argument 'timeout'
Traceback (most recent call last):
  File "/home/petto/news_search/index/es_indexer.py", line 134, in <module>
    es = Elasticsearch(
TypeError: Elasticsearch.__init__() got an unexpected keyword argument 'timeout'
2025-05-03 03:12:24,773 - INFO - HEAD http://localhost:9200/ [status:401 duration:0.068s]
2025-05-03 03:12:24,774 - CRITICAL - 程序异常终止: 无法连接到 Elasticsearch
Traceback (most recent call last):
  File "/home/petto/news_search/index/es_indexer.py", line 139, in <module>
    raise ConnectionError("无法连接到 Elasticsearch")
ConnectionError: 无法连接到 Elasticsearch
2025-05-03 03:14:22,420 - INFO - HEAD http://localhost:9200/ [status:401 duration:0.066s]
2025-05-03 03:14:22,420 - CRITICAL - 程序异常终止: 无法连接到 Elasticsearch
Traceback (most recent call last):
  File "/home/petto/news_search/index/es_indexer.py", line 139, in <module>
    raise ConnectionError("无法连接到 Elasticsearch")
ConnectionError: 无法连接到 Elasticsearch
2025-05-03 03:17:28,390 - INFO - HEAD http://localhost:9200/ [status:401 duration:0.069s]
2025-05-03 03:17:28,390 - CRITICAL - 程序异常终止: 无法连接到 Elasticsearch
Traceback (most recent call last):
  File "/home/petto/news_search/index/es_indexer.py", line 143, in <module>
    raise ConnectionError("无法连接到 Elasticsearch")
ConnectionError: 无法连接到 Elasticsearch
2025-05-03 03:20:40,271 - INFO - HEAD http://localhost:9200/ [status:200 duration:0.003s]
2025-05-03 03:20:40,273 - INFO - HEAD http://localhost:9200/university_notices [status:404 duration:0.001s]
2025-05-03 03:20:40,286 - INFO - PUT http://localhost:9200/university_notices [status:400 duration:0.013s]
2025-05-03 03:20:40,286 - ERROR - 创建索引失败: BadRequestError(400, 'illegal_argument_exception', 'Custom Analyzer [chinese_analyzer] failed to find tokenizer under name [ik_max_word]')
2025-05-03 03:20:40,286 - CRITICAL - 程序异常终止: BadRequestError(400, 'illegal_argument_exception', 'Custom Analyzer [chinese_analyzer] failed to find tokenizer under name [ik_max_word]')
Traceback (most recent call last):
  File "/home/petto/news_search/index/es_indexer.py", line 146, in <module>
    create_index(es)
  File "/home/petto/news_search/index/es_indexer.py", line 73, in create_index
    es.indices.create(index=CONFIG['index_name'], body=mapping)
  File "/home/petto/news_search/venv/lib/python3.10/site-packages/elasticsearch/_sync/client/utils.py", line 415, in wrapped
    return api(*args, **kwargs)
  File "/home/petto/news_search/venv/lib/python3.10/site-packages/elasticsearch/_sync/client/indices.py", line 705, in create
    return self.perform_request(  # type: ignore[return-value]
  File "/home/petto/news_search/venv/lib/python3.10/site-packages/elasticsearch/_sync/client/_base.py", line 422, in perform_request
    return self._client.perform_request(
  File "/home/petto/news_search/venv/lib/python3.10/site-packages/elasticsearch/_sync/client/_base.py", line 271, in perform_request
    response = self._perform_request(
  File "/home/petto/news_search/venv/lib/python3.10/site-packages/elasticsearch/_sync/client/_base.py", line 351, in _perform_request
    raise HTTP_EXCEPTIONS.get(meta.status, ApiError)(
elasticsearch.BadRequestError: BadRequestError(400, 'illegal_argument_exception', 'Custom Analyzer [chinese_analyzer] failed to find tokenizer under name [ik_max_word]')
2025-05-03 14:45:20,665 - INFO - HEAD http://localhost:9200/ [status:401 duration:0.080s]
2025-05-03 14:45:20,673 - CRITICAL - 程序异常终止: 无法连接到 Elasticsearch
Traceback (most recent call last):
  File "/home/petto/news_search/index/es_indexer.py", line 143, in <module>
    raise ConnectionError("无法连接到 Elasticsearch")
ConnectionError: 无法连接到 Elasticsearch
2025-05-03 14:46:16,071 - INFO - HEAD http://localhost:9200/ [status:401 duration:0.067s]
2025-05-03 14:46:16,071 - CRITICAL - 程序异常终止: 无法连接到 Elasticsearch
Traceback (most recent call last):
  File "/home/petto/news_search/index/es_indexer.py", line 143, in <module>
    raise ConnectionError("无法连接到 Elasticsearch")
ConnectionError: 无法连接到 Elasticsearch
2025-05-03 14:47:59,724 - INFO - HEAD http://localhost:9200/ [status:200 duration:0.002s]
2025-05-03 14:47:59,726 - INFO - HEAD http://localhost:9200/university_notices [status:404 duration:0.001s]
2025-05-03 14:48:00,080 - INFO - PUT http://localhost:9200/university_notices [status:200 duration:0.354s]
2025-05-03 14:48:00,080 - INFO - 索引 university_notices 创建成功
2025-05-03 14:48:00,425 - INFO - PUT http://localhost:9200/_bulk [status:200 duration:0.307s]
2025-05-03 14:48:00,619 - INFO - PUT http://localhost:9200/_bulk [status:200 duration:0.173s]
2025-05-03 14:48:00,822 - INFO - PUT http://localhost:9200/_bulk [status:200 duration:0.187s]
2025-05-03 14:48:01,091 - INFO - PUT http://localhost:9200/_bulk [status:200 duration:0.246s]
2025-05-03 14:48:01,287 - INFO - PUT http://localhost:9200/_bulk [status:200 duration:0.179s]
2025-05-03 14:48:01,531 - INFO - PUT http://localhost:9200/_bulk [status:200 duration:0.227s]
2025-05-03 14:48:01,716 - INFO - PUT http://localhost:9200/_bulk [status:200 duration:0.170s]
2025-05-03 14:48:01,950 - INFO - PUT http://localhost:9200/_bulk [status:200 duration:0.212s]
2025-05-03 14:48:02,062 - INFO - PUT http://localhost:9200/_bulk [status:200 duration:0.099s]
2025-05-03 14:48:02,064 - INFO - === 索引构建完成 ===
